<?xml version="1.0" encoding="utf-8"?>
<robot name="turtlebot3_burger">
  <material name="light_black">
    <color rgba="0.4 0.4 0.4 1" />
  </material>
  <material name="dark">
    <color rgba="0.3 0.3 0.3 1" />
  </material>
  <link name="base_footprint" />
  <link name="base_link">
    <inertial>
      <origin rpy="0 0 0" xyz="0 0 0" />
      <mass value="0.8257350326" />
      <inertia ixx="0.00221244152635336" ixy="-1.22940828077844E-05" ixz="3.49387228197884E-05" iyy="0.00211937050335109" iyz="-5.01213344250573E-06" izz="0.00200642715208232" />
    </inertial>
    <visual>
      <origin xyz="-0.032 0 0" />
      <geometry>
        <mesh filename="package://meshes/burger_base.stl" scale="0.001 0.001 0.001" />
      </geometry>
      <material name="light_black">
        <color rgba="0.4 0.4 0.4 1" />
      </material>
    </visual>
    <collision>
      <origin xyz="-0.032 0 0.07" />
      <geometry>
        <box size="0.14 0.14 0.143" />
      </geometry>
    </collision>
  </link>
  <link name="base_scan">
    <inertial>
      <origin rpy="0 0 0" xyz="0 0 0" />
      <mass value="0.1140000001" />
      <inertia ixx="0" ixy="0" ixz="0" iyy="0" iyz="0" izz="0" />
    </inertial>
    <visual>
      <geometry>
        <mesh filename="package://meshes/lds.stl" scale="0.001 0.001 0.001" />
      </geometry>
      <material name="dark">
        <color rgba="0.3 0.3 0.3 1" />
      </material>
    </visual>
    <collision>
      <origin xyz="0.015 0 -0.0065" />
      <geometry>
        <cylinder length="0.0315" radius="0.055" />
      </geometry>
    </collision>
  </link>
  <link name="imu_link" />
  <link name="caster_back_link">
    <inertial>
      <origin rpy="0 0 0" xyz="0 0 0" />
      <mass value="0.0049999999" />
      <inertia ixx="0" ixy="0" ixz="0" iyy="0" iyz="0" izz="0" />
    </inertial>
    <collision>
      <origin xyz="0 0.001 0" />
      <geometry>
        <box size="0.03 0.009 0.02" />
      </geometry>
    </collision>
  </link>
  <link name="wheel_right_link">
    <inertial>
      <origin rpy="0 0 0" xyz="0 0 0" />
      <mass value="0.0284989402" />
      <inertia ixx="0" ixy="0" ixz="0" iyy="0" iyz="0" izz="0" />
    </inertial>
    <visual>
      <origin rpy="-4.713185 0 0" />
      <geometry>
        <mesh filename="package://meshes/right_tire.stl" scale="0.001 0.001 0.001" />
      </geometry>
      <material name="dark">
        <color rgba="0.3 0.3 0.3 1" />
      </material>
    </visual>
    <collision>
      <geometry>
        <cylinder length="0.018" radius="0.033" />
      </geometry>
    </collision>
  </link>
  <link name="wheel_left_link">
    <inertial>
      <origin rpy="0 0 0" xyz="0 0 0" />
      <mass value="0.0284989402" />
      <inertia ixx="0" ixy="0" ixz="0" iyy="0" iyz="0" izz="0" />
    </inertial>
    <visual>
      <origin rpy="-4.713185 0 0" />
      <geometry>
        <mesh filename="package://meshes/left_tire.stl" scale="0.001 0.001 0.001" />
      </geometry>
      <material name="dark">
        <color rgba="0.3 0.3 0.3 1" />
      </material>
    </visual>
    <collision>
      <geometry>
        <cylinder length="0.018" radius="0.033" />
      </geometry>
    </collision>
  </link>
  <joint name="base_joint" type="fixed">
    <origin rpy="8.5E-05 0.076862 -6.263194" xyz="-0.025952 0.0007 0.145913" />
    <parent link="base_footprint" />
    <child link="base_link" />
  </joint>
  <joint name="scan_joint" type="fixed">
    <origin xyz="-0.032 0 0.172" />
    <parent link="base_link" />
    <child link="base_scan" />
  </joint>
  <joint name="imu_joint" type="fixed">
    <origin xyz="-0.032 0 0.068" />
    <parent link="base_link" />
    <child link="imu_link" />
  </joint>
  <joint name="caster_back_joint" type="fixed">
    <origin rpy="-1.57 0 0" xyz="-0.081 0 -0.004" />
    <parent link="base_link" />
    <child link="caster_back_link" />
  </joint>
  <joint name="wheel_right_joint" type="continuous">
    <origin rpy="-1.57 0 0" xyz="0 -0.08 0.023" />
    <parent link="base_link" />
    <child link="wheel_right_link" />
    <dynamics damping="10" friction="10" />
  </joint>
  <joint name="wheel_left_joint" type="continuous">
    <origin rpy="-1.57 0 0" xyz="0 0.08 0.023" />
    <parent link="base_link" />
    <child link="wheel_left_link" />
    <dynamics damping="10" friction="10" />
  </joint>
  <xacro:include filename="$(find turtlebot3_description)/urdf/common_properties.xacro" xmlns:xacro="http://ros.org/wiki/xacro" />
<xacro:include filename="$(find turtlebot3_description)/urdf/turtlebot3_burger.gazebo.xacro" xmlns:xacro="http://ros.org/wiki/xacro" />
</robot>